#VRML_SIM R2021a utf8
WorldInfo {
}
Viewpoint {
  orientation -0.9950369285117923 -0.0012437968084916848 0.09949856213693538 0.02512468257456667
  position 0.004958923305649616 0.4694372708429571 18.755731481278616
}
TexturedBackground {
}
TexturedBackgroundLight {
}
RectangleArena {
  rotation 1 0 0 1.5708
  floorSize 10 10
}
DEF Supervisor Robot {
  controller "openDoor"
  supervisor TRUE
}
DEF DOOR1 Door {
  translation -2.5 -4.25 0
  rotation 0.5773509358554485 0.5773489358556708 0.5773509358554485 2.0944
  name "door1"
  size 1.5 2.4 0.2
}
DEF DOOR2 Door {
  translation -1.125 2.75 0
  rotation 1 0 0 1.5708
  name "door2"
  size 1.25 2.4 0.2
}
Wall {
  translation -4 -2.75 1.23289e-06
  rotation 0.5773509358554485 0.5773489358556708 0.5773509358554485 2.0944
  size 2.5 2 0.1
}
Wall {
  translation -3.25 -1.5 0
  rotation 1 0 0 1.5708
  name "wall(1)"
  size 1.5 2 0.1
}
Wall {
  translation -2.5 -2.5 0
  rotation 0.5773509358554485 0.5773489358556708 0.5773509358554485 2.0944
  name "wall(2)"
  size 2 2 0.1
}
Wall {
  translation -1 -3 0
  rotation 1 0 0 1.5708
  name "wall(4)"
  size 3 2 0.1
}
Wall {
  translation 0 -1.5 0
  rotation 1.6952594753969508e-09 0.707104781184338 0.7071087811831002 -3.1415853071795863
  name "wall(7)"
  size 3 2 0.1
}
Wall {
  translation 2 3.75 0
  rotation 1.6952594753969508e-09 0.707104781184338 0.7071087811831002 -3.1415853071795863
  name "wall(8)"
  size 2 2 0.1
}
Wall {
  translation 4 2.75 0
  rotation 1.6952594753969508e-09 0.707104781184338 0.7071087811831002 -3.1415853071795863
  name "wall(9)"
  size 2 2 0.1
}
Wall {
  translation 0.5 2.75 0
  rotation 1.6952594753969508e-09 0.707104781184338 0.7071087811831002 -3.1415853071795863
  name "wall(11)"
  size 2 2 0.1
}
Wall {
  translation 3 3.25 0
  rotation 0.5773509358554485 0.5773489358556708 0.5773509358554485 2.0944
  name "wall(12)"
  size 1 2 0.1
}
Wall {
  translation 2.5 1.25 0
  rotation 1.6952594753969508e-09 0.707104781184338 0.7071087811831002 -3.1415853071795863
  name "wall(13)"
  size 2 2 0.1
}
Wall {
  translation 1.5 -0.5 0
  rotation 0.5773509358554485 0.5773489358556708 0.5773509358554485 2.0944
  name "wall(14)"
  size 6.5 2 0.1
}
Wall {
  translation 2.5 -3.75 0
  rotation 1.6952594753969508e-09 0.707104781184338 0.7071087811831002 -3.1415853071795863
  name "wall(15)"
  size 2 2 0.1
}
Wall {
  translation 3.5 -2.75 0
  rotation 0.5773509358554485 0.5773489358556708 0.5773509358554485 2.0944
  name "wall(16)"
  size 2 2 0.1
}
Wall {
  translation 4 -0.25 0
  rotation 1.6952594753969508e-09 0.707104781184338 0.7071087811831002 -3.1415853071795863
  name "wall(21)"
  size 2 2 0.1
}
Wall {
  translation -2.25 0.5 0
  rotation 1.6952594753969508e-09 0.707104781184338 0.7071087811831002 -3.1415853071795863
  name "wall(22)"
  size 3.5 2 0.1
}
Wall {
  translation -1.75 3.5 0
  rotation 0.5773509358554485 0.5773489358556708 0.5773509358554485 2.0944
  name "wall(23)"
  size 3 2 0.1
}
Wall {
  translation -2.25 2 0
  rotation 1.6952594753969508e-09 0.707104781184338 0.7071087811831002 -3.1415853071795863
  name "wall(25)"
  size 1 2 0.1
}
Wall {
  translation -4 2.75 0
  rotation 0.5773509358554485 0.5773489358556708 0.5773509358554485 2.0944
  name "wall(26)"
  size 2 2 0.1
}
Wall {
  translation -4 3.75 0
  rotation 1.6952594753969508e-09 0.707104781184338 0.7071087811831002 -3.1415853071795863
  name "wall(27)"
  size 2 2 0.1
}
Wall {
  translation -4 0 0
  rotation 0.5773509358554485 0.5773489358556708 0.5773509358554485 2.0944
  name "wall(29)"
  size 1 2 0.1
}
Robot {
  translation 4.5 4.5 0.04
  rotation 0 0 -1 -2.8797853071795863
  children [
    Lidar {
      translation 0 0 0.06
      rotation 0.5773509358554485 0.5773489358556708 0.5773509358554485 2.0943999999999994
      fieldOfView 3.14159
      numberOfLayers 1
      maxRange 8
      type "rotating"
    }
    GPS {
    }
    InertialUnit {
      rotation 0 0 1 1.5708
    }
    HingeJoint {
      jointParameters HingeJointParameters {
        axis 0 1 0
        anchor 0.06 0.07 0
      }
      device [
        RotationalMotor {
          name "motor1"
          maxVelocity 20
        }
      ]
      endPoint Solid {
        translation 0.060000000000000275 0.07000000000000028 3.469446951953614e-18
        children [
          DEF WHEEL Shape {
            geometry Cylinder {
              height 0.03
              radius 0.04
            }
          }
        ]
        boundingObject USE WHEEL
        physics Physics {
        }
      }
    }
    HingeJoint {
      jointParameters HingeJointParameters {
        axis 0 1 0
        anchor -0.06 0.07 0
      }
      device [
        RotationalMotor {
          name "motor2"
          maxVelocity 20
        }
      ]
      endPoint Solid {
        translation -0.05999999999999983 0.07000000000000028 3.469446951953614e-18
        children [
          Shape {
            geometry Cylinder {
              height 0.03
              radius 0.04
            }
          }
        ]
        name "solid(1)"
        boundingObject USE WHEEL
        physics Physics {
        }
      }
    }
    HingeJoint {
      jointParameters HingeJointParameters {
        axis 0 1 0
        anchor 0.06 -0.07 0
      }
      device [
        RotationalMotor {
          name "motor3"
          maxVelocity 20
        }
      ]
      endPoint Solid {
        translation 0.06000000000000005 -0.06999999999999984 3.469446951953614e-18
        children [
          Shape {
            geometry Cylinder {
              height 0.03
              radius 0.04
            }
          }
        ]
        name "solid(2)"
        boundingObject USE WHEEL
        physics Physics {
        }
      }
    }
    HingeJoint {
      jointParameters HingeJointParameters {
        axis 0 1 0
        anchor -0.06 -0.07 0
      }
      device [
        RotationalMotor {
          name "motor4"
          maxVelocity 20
        }
      ]
      endPoint Solid {
        translation -0.05999999999999983 -0.06999999999999984 3.469446951953614e-18
        children [
          Shape {
            geometry Cylinder {
              height 0.03
              radius 0.04
            }
          }
        ]
        name "solid(3)"
        boundingObject USE WHEEL
        physics Physics {
        }
      }
    }
    DEF BODY Shape {
      appearance PBRAppearance {
      }
      geometry Box {
        size 0.2 0.1 0.05
      }
    }
  ]
  name "car"
  boundingObject USE BODY
  physics Physics {
    density -1
    mass 1
  }
  controller "my_controller3"
}
